Workbook

Sheet Volume Container
B3: Type | C3: Volume | D3: m^3 | E3: Container (m) | F3: Gudang (m)
B4: 40FT | C4: 2360 | D4: 67 | E4: =D4^(1/3) -> 4.0615481 | F4: =SQRT(50000) -> 223.6068
B5: Build Up | C5: 1600
B6: 20FT | C6: 1160 | D6: 33
B7: FUSO | C7: 880
B8: CDD | C8: 280 | D8: 25
C10: 4623

Sheet Sheet14

Sheet Sulawesi
B3: Sulawesi | F3: 28495.968 | G3: Denpasar | H3: DC031 | I3: Direct CPU
B4: Wilayah | C4: Rerata Jarak | D4: Rerata Permintaan (boks/bulan) | F4: 6252 | G4: Kendari | H4: DC032 | I4: Direct CPU
B5: Amurang | C5: 18.071 | D5: 1729 | F5: 17215.408 | G5: Lombok | H5: DC033 | I5: Direct CPU
B6: Barru | C6: 10.64 | D6: 967 | F6: 8800 | G6: Makassar | H6: DC034 | I6: Direct CPU
B7: Bau-Bau | C7: 6.173 | D7: 2724 | F7: 6680 | G7: Manado | H7: DC035 | I7: Direct CPU
B8: Belopa | C8: 15.274 | D8: 1924 | F8: 7491 | G8: Palu | H8: DC036 | I8: Direct CPU
B9: Bitung | C9: 5.865 | D9: 2269
B10: Bone | C10: 15.975 | D10: 2871
B11: Bulukumba | C11: 26.986 | D11: 2549
B12: Gorontalo | C12: 14.201 | D12: 8017 | E12: =D12+D23 -> 10689
B13: Gowa | C13: 5.041 | D13: 11369
B14: Jeneponto | C14: 14.578 | D14: 2561
B15: Kendari | C15: 20.571 | D15: 6252 | E15: =D15+D7+D36+D16 -> 14736
B16: Kolaka | C16: 24.391 | D16: 3579
B17: Kotamobagu | C17: 8.049 | D17: 3692
B18: Luwuk | C18: 23.142 | D18: 9643
B19: Makassar | C19: 7.096 | D19: 8800 | E19: =D19+D11+D13+D14+D26+D32+D33+D10+D20+E24+E27 -> 62670
B20: Mamuju | C20: 16.957 | D20: 2902
B21: Manado | C21: 4.926 | D21: 6680 | E21: =D21+D9+D17+D34+E12 -> 25418
B22: Mangkutana | C22: 26.27 | D22: 4425
B23: Marisa | C23: 27.272 | D23: 2672
B24: Palopo | C24: 20.835 | D24: 3259 | E24: =D24+D8+D22+D35 -> 13393
B25: Palu | C25: 13.601 | D25: 7491 | E25: =D25+D30+D28+D18+D20 -> 23275
B26: Pangkep | C26: 8.625 | D26: 1826
B27: Pare-Pare | C27: 13.502 | D27: 5309 | E27: =D27+D6+D29+D31 -> 13252
B28: Parigi | C28: 20.277 | D28: 1223
B29: Polman | C29: 18.043 | D29: 3422
B30: Poso | C30: 20.928 | D30: 2016
B31: Sengkang | C31: 12.315 | D31: 3554
B32: Sinjai | C32: 10.669 | D32: 1169
B33: Takalar | C33: 5.803 | D33: 1978
B34: Tomohon | C34: 9.416 | D34: 2088
B35: Toraja | C35: 10.754 | D35: 3785
B36: Unaaha | C36: 23.65 | D36: 2181
B37: Grand Total | D37: =SUM(D4:D36) -> 124926

Sheet Kalimantan
B3: East Kalimantan(Customer POV)
B4: Wilayah | C4: Rerata Jarak | D4: Rerata Permintaan (boks/bulan)
B5: Ampah-Teweh | C5: 43.736 | D5: 4623
B6: Balikpapan | C6: 8.932 | D6: 16518 | E6: =D6+D16 -> 21193
B7: Banjarmasin | C7: 15.382 | D7: 22620 | E7: =D7+D8+D9+D17 -> 47169
B8: Barabai | C8: 31.066 | D8: 12496
B9: Batulicin | C9: 24.878 | D9: 7766
B10: Berau | C10: 38.022 | D10: 2879
B11: Bontang | C11: 3.592 | D11: 2010 | E11: =D11+D12 -> 3340
B12: Bontang-Sangata | C12: 3.514 | D12: 1330 | G12: 16518 | H12: Balikpapan | I12: DC037 | J12: Direct DC
B13: Ketapang | C13: 89.228 | D13: 208 | G13: 22620 | H13: Banjarmasin | I13: DC038 | J13: Direct DC
B14: Palangkaraya | C14: 9.204 | D14: 4632 | E14: =D14+D5 -> 9255 | G14: 2879 | H14: Berau | I14: DC039 | J14: Direct DC
B15: Pangkalanbun | C15: 8.186 | D15: 6285 | G15: 2010 | H15: Bontang | I15: DC040 | J15: Direct DC
B16: Penajam-Grogot | C16: 16.072 | D16: 4675 | G16: 4632 | H16: Palangkaraya | I16: DC041 | J16: Direct DC
B17: Rantau | C17: 13.288 | D17: 4287 | G17: 8377 | H17: Pontianak | I17: DC042 | J17: Direct DC
B18: Samarinda | C18: 9.821 | D18: 11295 | E18: =D18 -> 11295 | G18: 11295 | H18: Samarinda | I18: DC043 | J18: Direct DC
B19: Sampit | C19: 9.238 | D19: 4316 | E19: =D19+D15 -> 10601 | G19: 4316 | H19: Sampit | I19: DC044 | J19: Direct DC
B20: Sintang | C20: 301.356 | D20: 3 | G20: 12523 | H20: Tarakan | I20: DC045 | J20: Direct DC
B21: Tarakan | C21: 58.425 | D21: 12523 | E21: =D21 -> 12523
B22: West Kalimantan(Customer POV)
B23: Ketapang | C23: 73.283 | D23: 3105
B24: Pontianak | C24: 17.383 | D24: 8377 | E24: =D24+D25+D23+D26+D20+D13 -> 18499
B25: Singkawang | C25: 17.646 | D25: 3964
B26: Sintang | C26: 143.478 | D26: 2842
B27: Grand Total | D27: =SUM(D4:D26) -> 136754

Sheet BaliNusra
B3: BaliNusra
B4: Wilayah | C4: Rerata Jarak | D4: Rerata Permintaan (boks/bulan)
B5: BIMA | C5: 38.065991 | D5: =ROUNDUP(5782.422,0) -> 5783
B6: Denpasar | C6: 28.448189 | D6: =ROUNDUP(28495.968,0) -> 28496
B7: Kupang | C7: 58.323777 | D7: =ROUNDUP(8539.297,0) -> 8540
B8: Lombok | C8: 20.492709 | D8: =ROUNDUP(17215.408,0) -> 17216 | E8: =D8+D10+D5 -> 26518
B9: Maumere | C9: 30.513052 | D9: =ROUNDUP(2708.272,0) -> 2709
B10: Sumbawa | C10: 25.326844 | D10: =ROUNDUP(3518.842,0) -> 3519
B11: Grand Total | D11: =SUM(D5:D10) -> 66263
D27: =Sulawesi!D37+Kalimantan!D27+D11 -> 327943

Sheet Rate T&W
B3: Distributor Area | C3: ID | D3: Area | E3: Type | F3: Container | G3: Rate
B4: Bali Nusra | C4: DC031 | D4: Denpasar | E4: Direct CPU | F4: Build Up | G4: 12150000
B5: Bali Nusra | C5: DC031 | D5: Denpasar | E5: Direct CPU | F5: FUSO | G5: 8700000
B6: Bali Nusra | C6: DC033 | D6: Lombok | E6: Direct CPU | F6: Build Up | G6: 21440000
B7: Bali Nusra | C7: DC033 | D7: Lombok | E7: Direct CPU | F7: FUSO | G7: 16240000
B8: Bali Nusra | C8: DC033 | D8: Lombok | E8: Direct CPU | F8: CDD | G8: 12100000
B9: Sulawesi | C9: DC034 | D9: Makassar | E9: Direct CPU | F9: 40FT | G9: 17000000
B10: Sulawesi | C10: DC032 | D10: Kendari | E10: Direct CPU | F10: 40FT | G10: 28460000
B11: Sulawesi | C11: DC032 | D11: Kendari | E11: Direct CPU | F11: 20FT | G11: 17200000
B12: Sulawesi | C12: DC036 | D12: Palu | E12: Direct CPU | F12: 40FT | G12: 17250000
B13: Sulawesi | C13: DC036 | D13: Palu | E13: Direct CPU | F13: 20FT | G13: 10850000
B14: Sulawesi | C14: DC035 | D14: Manado | E14: Direct CPU | F14: 40FT | G14: 21900000
B15: Sulawesi | C15: DC035 | D15: Manado | E15: Direct CPU | F15: 20FT | G15: 13200000
... B30: Kalimantan | C30: DC045 | D30: Tarakan | E30: Direct DC | F30: 20FT | G30: 16174145

Sheet Total Biaya First Mile

Sheet Biaya Variable KendaraanTrip ti
E1: Biaya BBM/Trip | I1: Rate(Biaya/Kapasitas Volume)/1 Perjalanan | N1: Biaya BBM | S1: Type | T1: Volume | U1: Harga BBM | V1: Petrol Consumption (Rasio BBM) | W1: Harga Bahan Bakar/KM
A2: Kepulauan | B2: Daerah Asal | C2: Tujuan | D2: Jarak | E2: {=TRANSPOSE(S2:S5)} -> CDD | F2: CDE | G2: GrandMax | H2: Kijang | I2: {=TRANSPOSE(S2:S5)} -> CDD | J2: CDE | K2: GrandMax | L2: Kijang | N2: Harga Solar | O2: 6800 | S2: CDD | T2: 280 | V2: 4 | W2: =6800/4 -> 1700 | Y2: Harga Solar | Z2: 6800
N3: Harga Pertalite | O3: 10000 | P3: Cek BBM TERENDAH | R3: Cek RATE Terendah | S3: CDE | T3: 200 | V3: 7 | W3: =6800/7 -> 971.42857 | Y3: Harga Pertalite | Z3: 10000
A4: Bali Nusra | B4: Lombok | C4: Kupang | D4: 1046.393 | E4: =$D$4/$V$2*6800 -> 1778868.1 | F4: =$D$4/$V$3*6800 -> 1016496.1 | G4: =$D$4/$V$4*10000 -> 1307991.2 | H4: =$D$4/$V$5*10000 -> 1046393 | I4: =E4/$T$2 -> 6353.1004 | J4: =F4/$T$3 -> 5082.4803 | K4: =G4/$T$4 -> 10899.927 | L4: =H4/$T$5 -> 13079.913 | P4: =MIN(E4:H4) -> 1016496.1 | Q4: CDE | R4: =MIN(I4:L4) -> 5082.4803 | S4: GrandMax | T4: 120 | V4: 8 | W4: =10000/4 -> 2500
C5: Maumere | D5: 924.619 | E5: =D5/$V$2*6800 -> 1571852.3 | F5: =D5/$V$3*6800 -> 898201.31 | G5: =D5/$V$4*10000 -> 1155773.8 | H5: =D5/$V$5*10000 -> 924619 | I5: =E5/$T$2 -> 5613.7582 | J5: =F5/$T$3 -> 4491.0066 | K5: =G5/$T$4 -> 9631.4479 | L5: =H5/$T$5 -> 11557.737 | P5: =MIN(E5:H5) -> 898201.31 | Q5: CDE | R5: =MIN(I5:L5) -> 4491.0066 | S5: Kijang | T5: 80 | V5: 10 | W5: =10000/10 -> 1000
C6: Sumbawa | D6: 179.485 | E6: =D6/$V$2*6800 -> 305124.5 | F6: =D6/$V$3*6800 -> 174356.86 | G6: =D6/$V$4*10000 -> 224356.25 | H6: =D6/$V$5*10000 -> 179485 | I6: =E6/$T$2 -> 1089.7304 | J6: =F6/$T$3 -> 871.78429 | K6: =G6/$T$4 -> 1869.6354 | L6: =H6/$T$5 -> 2243.5625 | P6: =MIN(E6:H6) -> 174356.86 | Q6: CDE | R6: =MIN(I6:L6) -> 871.78429 | S6: Motorbike | T6: 5 | V6: 15 | W6: =10000/15 -> 666.66667
D7: 440.971 | E7: =D7/$V$2*6800 -> 749650.7 | F7: =D7/$V$3*6800 -> 428371.83 | G7: =D7/$V$4*10000 -> 551213.75 | H7: =D7/$V$5*10000 -> 440971 | I7: =E7/$T$2 -> 2677.3239 | J7: =F7/$T$3 -> 2141.8591 | K7: =G7/$T$4 -> 4593.4479 | L7: =H7/$T$5 -> 5512.1375 | S7: https://drive.google.com/file/d/16zUUoSwMh_7Tqi-kTA__gdN4c5aFTCR9/view?usp=drive_link
A8: Kalimantan | B8: Balikpapan | C8: Penajam-Grogot | D8: 161.958 | E8: =D8/$V$2*6800 -> 275328.6 | F8: =D8/$V$3*6800 -> 157330.63 | G8: =D8/$V$4*10000 -> 202447.5 | H8: =D8/$V$5*10000 -> 161958 | I8: =E8/$T$2 -> 983.31643 | J8: =F8/$T$3 -> 786.65314 | K8: =G8/$T$4 -> 1687.0625 | L8: =H8/$T$5 -> 2024.475 | P8: =MIN(E8:H8) -> 157330.63 | Q8: CDE | R8: =MIN(I8:L8) -> 786.65314
A9: Kalimantan | B9: Banjarmasin | C9: Barabai | D9: 144.846 | E9: =D9/$V$2*6800 -> 246238.2 | F9: =D9/$V$3*6800 -> 140707.54 | G9: =D9/$V$4*10000 -> 181057.5 | H9: =D9/$V$5*10000 -> 144846 | I9: =E9/$T$2 -> 879.42214 | J9: =F9/$T$3 -> 703.53771 | K9: =G9/$T$4 -> 1508.8125 | L9: =H9/$T$5 -> 1810.575 | P9: =MIN(E9:H9) -> 140707.54 | Q9: CDE | R9: =MIN(I9:L9) -> 703.53771
C10: Batulicin | D10: 203.111 | E10: =D10/$V$2*6800 -> 345288.7 | F10: =D10/$V$3*6800 -> 197307.83 | G10: =D10/$V$4*10000 -> 253888.75 | H10: =D10/$V$5*10000 -> 203111 | I10: =E10/$T$2 -> 1233.1739 | J10: =F10/$T$3 -> 986.53914 | K10: =G10/$T$4 -> 2115.7396 | L10: =H10/$T$5 -> 2538.8875 | P10: =MIN(E10:H10) -> 197307.83 | Q10: CDE | R10: =MIN(I10:L10) -> 986.53914
C11: Rantau | D11: 94.264 | E11: =D11/$V$2*6800 -> 160248.8 | F11: =D11/$V$3*6800 -> 91570.743 | G11: =D11/$V$4*10000 -> 117830 | H11: =D11/$V$5*10000 -> 94264 | I11: =E11/$T$2 -> 572.31714 | J11: =F11/$T$3 -> 457.85371 | K11: =G11/$T$4 -> 981.91667 | L11: =H11/$T$5 -> 1178.3 | P11: =MIN(E11:H11) -> 91570.743 | Q11: CDE | R11: =MIN(I11:L11) -> 457.85371
A12: Kalimantan | B12: Bontang | C12: Bontang-Sangata | D12: 59.2 | E12: =D12/$V$2*6800 -> 100640 | F12: =D12/$V$3*6800 -> 57508.571 | G12: =D12/$V$4*10000 -> 74000 | H12: =D12/$V$5*10000 -> 59200 | I12: =E12/$T$2 -> 359.42857 | J12: =F12/$T$3 -> 287.54286 | K12: =G12/$T$4 -> 616.66667 | L12: =H12/$T$5 -> 740 | P12: =MIN(E12:H12) -> 57508.571 | Q12: CDE | R12: =MIN(I12:L12) -> 287.54286
A13: Kalimantan | B13: Palangkaraya | C13: Ampah | D13: 343.092 | E13: =D13/$V$2*6800 -> 583256.4 | F13: =D13/$V$3*6800 -> 333289.37 | G13: =D13/$V$4*10000 -> 428865 | H13: =D13/$V$5*10000 -> 343092 | I13: =E13/$T$2 -> 2083.0586 | J13: =F13/$T$3 -> 1666.4469 | K13: =G13/$T$4 -> 3573.875 | L13: =H13/$T$5 -> 4288.65 | P13: =MIN(E13:H13) -> 333289.37 | Q13: CDE | R13: =MIN(I13:L13) -> 1666.4469
A14: Kalimantan | B14: Pontianak | C14: Ketapang | D14: 352.4 | E14: =D14/$V$2*6800 -> 599080 | F14: =D14/$V$3*6800 -> 342331.43 | G14: =D14/$V$4*10000 -> 440500 | H14: =D14/$V$5*10000 -> 352400 | I14: =E14/$T$2 -> 2139.5714 | J14: =F14/$T$3 -> 1711.6571 | K14: =G14/$T$4 -> 3670.8333 | L14: =H14/$T$5 -> 4405 | P14: =MIN(E14:H14) -> 342331.43 | Q14: CDE | R14: =MIN(I14:L14) -> 1711.6571
C15: Singkawang | D15: 151 | E15: =D15/$V$2*6800 -> 256700 | F15: =D15/$V$3*6800 -> 146685.71 | G15: =D15/$V$4*10000 -> 188750 | H15: =D15/$V$5*10000 -> 151000 | I15: =E15/$T$2 -> 916.78571 | J15: =F15/$T$3 -> 733.42857 | K15: =G15/$T$4 -> 1572.9167 | L15: =H15/$T$5 -> 1887.5 | P15: =MIN(E15:H15) -> 146685.71 | Q15: CDE | R15: =MIN(I15:L15) -> 733.42857
C16: Sintang | D16: 321 | E16: =D16/$V$2*6800 -> 545700 | F16: =D16/$V$3*6800 -> 311828.57 | G16: =D16/$V$4*10000 -> 401250 | H16: =D16/$V$5*10000 -> 321000 | I16: =E16/$T$2 -> 1948.9286 | J16: =F16/$T$3 -> 1559.1429 | K16: =G16/$T$4 -> 3343.75 | L16: =H16/$T$5 -> 4012.5 | P16: =MIN(E16:H16) -> 311828.57 | Q16: CDE | R16: =MIN(I16:L16) -> 1559.1429
A17: Kalimantan | B17: Sampit | C17: Pangkalanbun | D17: 212.077 | E17: =$D$4/$V$2*6800 -> 1778868.1 | F17: =$D$4/$V$3*6800 -> 1016496.1 | G17: =$D$4/$V$4*10000 -> 1307991.2 | H17: =$D$4/$V$5*10000 -> 1046393 | I17: =E17/$T$2 -> 6353.1004 | J17: =F17/$T$3 -> 5082.4803 | K17: =G17/$T$4 -> 10899.927 | L17: =H17/$T$5 -> 13079.913 | P17: =MIN(E17:H17) -> 1016496.1 | Q17: CDE | R17: =MIN(I17:L17) -> 5082.4803
A18: Sulawesi | B18: Kendari | C18: Kolaka | D18: 154.22 | E18: =D18/$V$2*6800 -> 262174 | F18: =D18/$V$3*6800 -> 149813.71 | G18: =D18/$V$4*10000 -> 192775 | H18: =D18/$V$5*10000 -> 154220 | I18: =E18/$T$2 -> 936.33571 | J18: =F18/$T$3 -> 749.06857 | K18: =G18/$T$4 -> 1606.4583 | L18: =H18/$T$5 -> 1927.75 | P18: =MIN(E18:H18) -> 149813.71 | Q18: CDE | R18: =MIN(I18:L18) -> 749.06857
C19: Unaaha | D19: 13.78 | E19: =D19/$V$2*6800 -> 23426 | F19: =D19/$V$3*6800 -> 13386.286 | G19: =D19/$V$4*10000 -> 17225 | H19: =D19/$V$5*10000 -> 13780 | I19: =E19/$T$2 -> 83.664286 | J19: =F19/$T$3 -> 66.931429 | K19: =G19/$T$4 -> 143.54167 | L19: =H19/$T$5 -> 172.25 | P19: =MIN(E19:H19) -> 13386.286 | Q19: CDE | R19: =MIN(I19:L19) -> 66.931429
C20: Bau Bau | D20: 275.58 | E20: =D20/$V$2*6800 -> 468486 | F20: =D20/$V$3*6800 -> 267706.29 | G20: =D20/$V$4*10000 -> 344475 | H20: =D20/$V$5*10000 -> 275580 | I20: =E20/$T$2 -> 1673.1643 | J20: =F20/$T$3 -> 1338.5314 | K20: =G20/$T$4 -> 2870.625 | L20: =H20/$T$5 -> 3444.75 | P20: =MIN(E20:H20) -> 267706.29 | Q20: CDE | R20: =MIN(I20:L20) -> 1338.5314
A21: Sulawesi | B21: Manado | C21: Amurang | D21: 55.4 | E21: =D21/$V$2*6800 -> 94180 | F21: =D21/$V$3*6800 -> 53817.143 | G21: =D21/$V$4*10000 -> 69250 | H21: =D21/$V$5*10000 -> 55400 | I21: =E21/$T$2 -> 336.35714 | J21: =F21/$T$3 -> 269.08571 | K21: =G21/$T$4 -> 577.08333 | L21: =H21/$T$5 -> 692.5 | P21: =MIN(E21:H21) -> 53817.143 | Q21: CDE | R21: =MIN(I21:L21) -> 269.08571
C22: Bitung | D22: 47.8 | E22: =D22/$V$2*6800 -> 81260 | F22: =D22/$V$3*6800 -> 46434.286 | G22: =D22/$V$4*10000 -> 59750 | H22: =D22/$V$5*10000 -> 47800 | I22: =E22/$T$2 -> 290.21429 | J22: =F22/$T$3 -> 232.17143 | K22: =G22/$T$4 -> 497.91667 | L22: =H22/$T$5 -> 597.5 | P22: =MIN(E22:H22) -> 46434.286 | Q22: CDE | R22: =MIN(I22:L22) -> 232.17143
C23: Kotamobagu | D23: 170.45 | E23: =D23/$V$2*6800 -> 289765 | F23: =D23/$V$3*6800 -> 165580 | G23: =D23/$V$4*10000 -> 213062.5 | H23: =D23/$V$5*10000 -> 170450 | I23: =E23/$T$2 -> 1034.875 | J23: =F23/$T$3 -> 827.9 | K23: =G23/$T$4 -> 1775.5208 | L23: =H23/$T$5 -> 2130.625 | P23: =MIN(E23:H23) -> 165580 | Q23: CDE | R23: =MIN(I23:L23) -> 827.9
C24: Tomohon | D24: 35.19 | E24: =D24/$V$2*6800 -> 59823 | F24: =D24/$V$3*6800 -> 34184.571 | G24: =D24/$V$4*10000 -> 43987.5 | H24: =D24/$V$5*10000 -> 35190 | I24: =E24/$T$2 -> 213.65357 | J24: =F24/$T$3 -> 170.92286 | K24: =G24/$T$4 -> 366.5625 | L24: =H24/$T$5 -> 439.875 | P24: =MIN(E24:H24) -> 34184.571 | Q24: CDE | R24: =MIN(I24:L24) -> 170.92286
C25: Gorontalo | D25: 396.91 | E25: =D25/$V$2*6800 -> 674747 | F25: =D25/$V$3*6800 -> 385569.71 | G25: =D25/$V$4*10000 -> 496137.5 | H25: =D25/$V$5*10000 -> 396910 | I25: =E25/$T$2 -> 2409.8107 | J25: =F25/$T$3 -> 1927.8486 | K25: =G25/$T$4 -> 4134.4792 | L25: =H25/$T$5 -> 4961.375 | P25: =MIN(E25:H25) -> 385569.71 | Q25: CDE | R25: =MIN(I25:L25) -> 1927.8486
A26: Sulawesi | B26: Makassar | C26: Bulukumba | D26: 200 | E26: =D26/$V$2*6800 -> 340000 | F26: =D26/$V$3*6800 -> 194285.71 | G26: =D26/$V$4*10000 -> 250000 | H26: =D26/$V$5*10000 -> 200000 | I26: =E26/$T$2 -> 1214.2857 | J26: =F26/$T$3 -> 971.42857 | K26: =G26/$T$4 -> 2083.3333 | L26: =H26/$T$5 -> 2500 | P26: =MIN(E26:H26) -> 194285.71 | Q26: CDE | R26: =MIN(I26:L26) -> 971.42857
C27: Gowa | D27: 16.37 | E27: =D27/$V$2*6800 -> 27829 | F27: =D27/$V$3*6800 -> 15902.286 | G27: =D27/$V$4*10000 -> 20462.5 | H27: =D27/$V$5*10000 -> 16370 | I27: =E27/$T$2 -> 99.389286 | J27: =F27/$T$3 -> 79.511429 | K27: =G27/$T$4 -> 170.52083 | L27: =H27/$T$5 -> 204.625 | P27: =MIN(E27:H27) -> 15902.286 | Q27: CDE | R27: =MIN(I27:L27) -> 79.511429
C28: Jeneponto | D28: 97.42 | E28: =D28/$V$2*6800 -> 165614 | F28: =D28/$V$3*6800 -> 94636.571 | G28: =D28/$V$4*10000 -> 121775 | H28: =D28/$V$5*10000 -> 97420 | I28: =E28/$T$2 -> 591.47857 | J28: =F28/$T$3 -> 473.18286 | K28: =G28/$T$4 -> 1014.7917 | L28: =H28/$T$5 -> 1217.75 | P28: =MIN(E28:H28) -> 94636.571 | Q28: CDE | R28: =MIN(I28:L28) -> 473.18286
C29: Pangkep | D29: 55.23 | E29: =D29/$V$2*6800 -> 93891 | F29: =D29/$V$3*6800 -> 53652 | G29: =D29/$V$4*10000 -> 69037.5 | H29: =D29/$V$5*10000 -> 55230 | I29: =E29/$T$2 -> 335.325 | J29: =F29/$T$3 -> 268.26 | K29: =G29/$T$4 -> 575.3125 | L29: =H29/$T$5 -> 690.375 | P29: =MIN(E29:H29) -> 53652 | Q29: CDE | R29: =MIN(I29:L29) -> 268.26
C30: Takalar | D30: 41.33 | E30: =D30/$V$2*6800 -> 70261 | F30: =D30/$V$3*6800 -> 40149.143 | G30: =D30/$V$4*10000 -> 51662.5 | H30: =D30/$V$5*10000 -> 41330 | I30: =E30/$T$2 -> 250.93214 | J30: =F30/$T$3 -> 200.74571 | K30: =G30/$T$4 -> 430.52083 | L30: =H30/$T$5 -> 516.625 | P30: =MIN(E30:H30) -> 40149.143 | Q30: CDE | R30: =MIN(I30:L30) -> 200.74571
C31: Bone | D31: 194.85 | E31: =D31/$V$2*6800 -> 331245 | F31: =D31/$V$3*6800 -> 189282.86 | G31: =D31/$V$4*10000 -> 243562.5 | H31: =D31/$V$5*10000 -> 194850 | I31: =E31/$T$2 -> 1183.0179 | J31: =F31/$T$3 -> 946.41429 | K31: =G31/$T$4 -> 2029.6875 | L31: =H31/$T$5 -> 2435.625 | P31: =MIN(E31:H31) -> 189282.86 | Q31: CDE | R31: =MIN(I31:L31) -> 946.41429
C32: Palopo | D32: 375.38 | E32: =D32/$V$2*6800 -> 638146 | F32: =D32/$V$3*6800 -> 364654.86 | G32: =D32/$V$4*10000 -> 469225 | H32: =D32/$V$5*10000 -> 375380 | I32: =E32/$T$2 -> 2279.0929 | J32: =F32/$T$3 -> 1823.2743 | K32: =G32/$T$4 -> 3910.2083 | L32: =H32/$T$5 -> 4692.25 | P32: =MIN(E32:H32) -> 364654.86 | Q32: CDE | R32: =MIN(I32:L32) -> 1823.2743
C33: Pare-Pare | D33: 162.64 | E33: =D33/$V$2*6800 -> 276488 | F33: =D33/$V$3*6800 -> 157993.14 | G33: =D33/$V$4*10000 -> 203300 | H33: =D33/$V$5*10000 -> 162640 | I33: =E33/$T$2 -> 987.45714 | J33: =F33/$T$3 -> 789.96571 | K33: =G33/$T$4 -> 1694.1667 | L33: =H33/$T$5 -> 2033 | P33: =MIN(E33:H33) -> 157993.14 | Q33: CDE | R33: =MIN(I33:L33) -> 789.96571
C34: Sinjai | D34: 224.38 | E34: =D34/$V$2*6800 -> 381446 | F34: =D34/$V$3*6800 -> 217969.14 | G34: =D34/$V$4*10000 -> 280475 | H34: =D34/$V$5*10000 -> 224380 | I34: =E34/$T$2 -> 1362.3071 | J34: =F34/$T$3 -> 1089.8457 | K34: =G34/$T$4 -> 2337.2917 | L34: =H34/$T$5 -> 2804.75 | P34: =MIN(E34:H34) -> 217969.14 | Q34: CDE | R34: =MIN(I34:L34) -> 1089.8457
A35: Sulawesi | B35: Palu | C35: Parigi | D35: 71.72 | E35: =D35/$V$2*6800 -> 121924 | F35: =D35/$V$3*6800 -> 69670.857 | G35: =D35/$V$4*10000 -> 89650 | H35: =D35/$V$5*10000 -> 71720 | I35: =E35/$T$2 -> 435.44286 | J35: =F35/$T$3 -> 348.35429 | K35: =G35/$T$4 -> 747.08333 | L35: =H35/$T$5 -> 896.5 | P35: =MIN(E35:H35) -> 69670.857 | Q35: CDE | R35: =MIN(I35:L35) -> 348.35429
C36: Luwuk | D36: 589.5 | E36: =D36/$V$2*6800 -> 1002150 | F36: =D36/$V$3*6800 -> 572657.14 | G36: =D36/$V$4*10000 -> 736875 | H36: =D36/$V$5*10000 -> 589500 | I36: =E36/$T$2 -> 3579.1071 | J36: =F36/$T$3 -> 2863.2857 | K36: =G36/$T$4 -> 6140.625 | L36: =H36/$T$5 -> 7368.75 | P36: =MIN(E36:H36) -> 572657.14 | Q36: CDE | R36: =MIN(I36:L36) -> 2863.2857
C37: Mamuju | D37: 406.82 | E37: =D37/$V$2*6800 -> 691594 | F37: =D37/$V$3*6800 -> 395196.57 | G37: =D37/$V$4*10000 -> 508525 | H37: =D37/$V$5*10000 -> 406820 | I37: =E37/$T$2 -> 2469.9786 | J37: =F37/$T$3 -> 1975.9829 | K37: =G37/$T$4 -> 4237.7083 | L37: =H37/$T$5 -> 5085.25 | P37: =MIN(E37:H37) -> 395196.57 | Q37: CDE | R37: =MIN(I37:L37) -> 1975.9829
C38: Poso | D38: 206.67 | E38: =D38/$V$2*6800 -> 351339 | F38: =D38/$V$3*6800 -> 200765.14 | G38: =D38/$V$4*10000 -> 258337.5 | H38: =D38/$V$5*10000 -> 206670 | I38: =E38/$T$2 -> 1254.7821 | J38: =F38/$T$3 -> 1003.8257 | K38: =G38/$T$4 -> 2152.8125 | L38: =H38/$T$5 -> 2583.375 | P38: =MIN(E38:H38) -> 200765.14 | Q38: CDE | R38: =MIN(I38:L38) -> 1003.8257
A39: Sulawesi | B39: Gorontalo | C39: Marissa | D39: 134.66 | E39: =D39/$V$2*6800 -> 228922 | F39: =D39/$V$3*6800 -> 130812.57 | G39: =D39/$V$4*10000 -> 168325 | H39: =D39/$V$5*10000 -> 134660 | I39: =E39/$T$2 -> 817.57857 | J39: =F39/$T$3 -> 654.06286 | K39: =G39/$T$4 -> 1402.7083 | L39: =H39/$T$5 -> 1683.25 | P39: =MIN(E39:H39) -> 130812.57 | Q39: CDE | R39: =MIN(I39:L39) -> 654.06286
A40: Sulawesi | B40: Palopo | C40: Belopa | D40: 49.98 | E40: =D40/$V$2*6800 -> 84966 | F40: =D40/$V$3*6800 -> 48552 | G40: =D40/$V$4*10000 -> 62475 | H40: =D40/$V$5*10000 -> 49980 | I40: =E40/$T$2 -> 303.45 | J40: =F40/$T$3 -> 242.76 | K40: =G40/$T$4 -> 520.625 | L40: =H40/$T$5 -> 624.75 | P40: =MIN(E40:H40) -> 48552 | Q40: CDE | R40: =MIN(I40:L40) -> 242.76
...

Sheet Biaya Penambahan Vehicle
A1: Distributor Area | B1: Area | C1: Type | D1: CDD Cost | E1: CDE Cost | F1: GrandMax Cost | G1: Kijang Cost
A2: Bali Nusra | B2: Denpasar | C2: Direct CPU | D2: 6900000 | E2: 5500000 | F2: 3500000 | I2: motor tidak digunakan karena rate-nya terlalu besar untuk penyewaan saja 1.2 juta, tetapi box yang dikirim tidak sampai 20 box
A3: Bali Nusra | B3: Lombok | C3: Direct CPU | D3: 6900000 | E3: 5500000 | F3: 3500000 | I3: Sewa Motor Bulanan Harian di Bali Kuta Mulai 80 Ribu Per Hari
A4: Bali Nusra | B4: BIMA | C4: Indirect DC | D4: 6900000 | E4: 5500000 | F4: 3500000
A5: Bali Nusra | B5: Kupang | C5: Indirect DC | D5: 6900000 | E5: 5500000 | F5: 3500000
A6: Bali Nusra | B6: Maumere | C6: Indirect DC | D6: 6900000 | E6: 5500000 | F6: 3500000
A7: Bali Nusra | B7: Sumbawa | C7: Indirect DC | D7: 6900000 | E7: 5500000 | F7: 3500000
A8: Kalimantan | B8: Sintang | C8: Depo | D8: 13853970 | E8: 6560843.3 | F8: 6560843.3 | G8: 6560843.3
A9: Kalimantan | B9: Balikpapan | C9: Direct DC | D9: 13853970 | E9: 6560843.3 | F9: 6560843.3 | G9: 6560843.3
A10: Kalimantan | B10: Banjarmasin | C10: Direct DC | D10: 13853970 | E10: 6560843.3 | F10: 6560843.3 | G10: 6560843.3
A11: Kalimantan | B11: Berau | C11: Direct DC | D11: 13853970 | E11: 6560843.3 | F11: 6560843.3 | G11: 6560843.3
A12: Kalimantan | B12: Bontang | C12: Direct DC | D12: 13853970 | E12: 6560843.3 | F12: 6560843.3 | G12: 6560843.3
A13: Kalimantan | B13: Palangkaraya | C13: Direct DC | D13: 13853970 | E13: 6560843.3 | F13: 6560843.3 | G13: 6560843.3
A14: Kalimantan | B14: Pontianak | C14: Direct DC | D14: 13853970 | E14: 6560843.3 | F14: 6560843.3 | G14: 6560843.3
A15: Kalimantan | B15: Samarinda | C15: Direct DC | D15: 13853970 | E15: 6560843.3 | F15: 6560843.3 | G15: 6560843.3
A16: Kalimantan | B16: Sampit | C16: Direct DC | D16: 13853970 | E16: 6560843.3 | F16: 6560843.3 | G16: 6560843.3
A17: Kalimantan | B17: Tarakan | C17: Direct DC | D17: 13853970 | E17: 6560843.3 | F17: 6560843.3 | G17: 6560843.3
A18: Sulawesi | B18: Kendari | C18: Direct CPU | D18: 6900000 | E18: 5500000 | F18: 3500000
A19: Sulawesi | B19: Makassar | C19: Direct CPU | D19: 6900000 | E19: 5500000 | F19: 3500000
A20: Sulawesi | B20: Manado | C20: Direct CPU | D20: 6900000 | E20: 5500000 | F20: 3500000
A21: Sulawesi | B21: Palu | C21: Direct CPU | D21: 6900000 | E21: 5500000 | F21: 3500000
A22: Sulawesi | B22: Bau-Bau | C22: Indirect DC | D22: 6900000 | E22: 5500000 | F22: 3500000
A23: Sulawesi | B23: Bone | C23: Indirect DC | D23: 6900000 | E23: 5500000 | F23: 3500000
A24: Sulawesi | B24: Gorontalo | C24: Indirect DC | D24: 6900000 | E24: 5500000 | F24: 3500000
A25: Sulawesi | B25: Luwuk | C25: Indirect DC | D25: 6900000 | E25: 5500000 | F25: 3500000
A26: Sulawesi | B26: Mamuju | C26: Indirect DC | D26: 6900000 | E26: 5500000 | F26: 3500000
A27: Sulawesi | B27: Palopo | C27: Indirect DC | D27: 6900000 | E27: 5500000 | F27: 3500000
A28: Sulawesi | B28: Pare-Pare | C28: Indirect DC | D28: 6900000 | E28: 5500000 | F28: 3500000
A29: Sulawesi | B29: Poso | C29: Indirect DC | D29: 6900000 | E29: 5500000 | F29: 3500000

Sheet Penjelasan Gurobi dan Model
A1: Tujuan Model: | F1: Bagian 2: Variabel Keputusan | J1: Bagian 3: Fungsi Tujuan (Objective Function) | R1: Bagian 4: Pembatasan (Constraints) | T1: Bagian 5: Penyelesaian (Optimization) dan Output
A3: Model ini bertujuan untuk mengoptimalkan pengiriman barang dengan meminimalkan total biaya yang terdiri dari dua komponen utama: | F3: Pada bagian ini, kita mendefinisikan variabel keputusan yang akan digunakan dalam model optimasi. | J3: Fungsi tujuan dalam model ini adalah untuk meminimalkan biaya yang terdiri dari dua komponen: | R3: a. Demand Harus Terpenuhi: | T3: Setelah semua variabel dan pembatasan ditentukan, model diselesaikan dengan m.optimize() dan hasilnya ditampilkan.
A5: Biaya BBM: Tergantung pada konsumsi bahan bakar kendaraan dan jarak tempuh. | F5: x = {} # binary: trip kendaraan k ke tujuan j pada trip ke-t | J5: Biaya BBM yang dihitung berdasarkan jarak, konsumsi bahan bakar, dan harga bahan bakar kendaraan. | R5: Model harus memastikan bahwa jumlah barang yang dikirim ke setiap tujuan selama seluruh trip harus lebih besar atau sama dengan demand tujuan tersebut. | T5: m.optimize()
A6: Biaya penambahan kendaraan: Tergantung pada berapa banyak kendaraan yang digunakan. | J6: Biaya penambahan kendaraan, yaitu biaya tetap yang perlu dikeluarkan jika menambah kendaraan baru.
F7: y = {} # integer: barang dikirim kendaraan k ke tujuan j pada trip t | R7: for j_row in tujuan.itertuples(): | T7: if m.status == GRB.OPTIMAL:
A8: Bagian 1: Input Data | J8: obj = gp.LinExpr()
F9: z = {} # binary: apakah kendaraan k dipakai | R9: m.addConstr( | T9: print("\nStatus:", m.Status)
A10: Di bagian awal, kita mendefinisikan data tujuan dan data kendaraan, serta harga bahan bakar. | J10: # Menambahkan biaya BBM
F11: v = {} # jumlah kendaraan yang digunakan per jenis kendaraan | R11: gp.quicksum(y[(k.Type, j_row.ID_Tujuan, t)] for k in kendaraan.itertuples() for t in range(MAX_TRIPS)) >= j_row.Demand, | T11: print("\n--- Hasil Pengiriman ---")
A12: a. Data Tujuan: | J12: for k_row in kendaraan.itertuples():
F13: xk,j,tx_{k,j,t}: Variabel biner yang menunjukkan apakah kendaraan k mengirim barang ke tujuan j pada trip t. | R13: name=f"demand_{j_row.ID_Tujuan}" | T13: total_biaya = m.ObjVal
A14: Data ini berisi informasi mengenai tujuan pengiriman: | F14: yk,j,ty_{k,j,t}: Variabel integer yang menunjukkan jumlah barang yang dikirim oleh kendaraan k ke tujuan j pada trip t. | J14: for j_row in tujuan.itertuples():
F15: zk,iz_{k,i}: Variabel biner yang menunjukkan apakah kendaraan k dipakai pada trip ke i. | R15: ) | T15: total_kendaraan = 0 # Variabel untuk menghitung total kendaraan yang digunakan
A16: ID_Tujuan: Kode untuk masing-masing tujuan (misalnya DC009, DC010, dll.). | J16: for t in range(MAX_TRIPS):
A17: Kota: Nama kota atau area yang menjadi tujuan. | R17: b. Kapasitas Kendaraan: | T17: for k, j, t in x:
A18: Jarak: Jarak dari titik asal ke tujuan (dalam kilometer). | J18: jarak = j_row.Jarak
A19: Demand: Jumlah barang yang harus dikirim ke tujuan tersebut. | R19: Jumlah barang yang dikirim oleh kendaraan k ke tujuan j pada trip t tidak boleh lebih dari kapasitas kendaraan. | T19: if x[(k, j, t)].X > 0.5:
J20: konsumsi = k_row.Cons
A21: tujuan_data = { | R21: for k_row in kendaraan.itertuples(): | T21: print(f"Kendaraan {k} mengirim {int(y[(k, j, t)].X)} unit ke {j} pada trip ke-{t+1}")
J22: bbm = harga_bbm[k_row.BBM]
A23: ID_Tujuan': ['DC009','DC010','DC011','DC018','DC027','DC048','DC054','DC055'], | R23: for j in tujuan['ID_Tujuan']: | T23: kendaraan_digunakan = {}
J24: biaya_per_trip = 2*(jarak / konsumsi) * bbm # 2x untuk pulang-pergi
A25: Kota': ['Bulukumba','Gowa','Jeneponto','Pangkep','Takalar','Bone','Palopo','Pare-Pare'], | R25: for t in range(MAX_TRIPS): | T25: for k_row in kendaraan.itertuples():
J26: obj += biaya_per_trip * x[(k_row.Type, j_row.ID_Tujuan, t)]
A27: Jarak': [200, 16.37, 97.42, 55.23, 41.33, 194.85, 375.38, 162.64], | R27: m.addConstr( | T27: for i in range(1, 20): # Asumsi hingga 5 kendaraan per jenis
J28: # Menambahkan biaya kendaraan
A29: Demand': [2549, 11369, 2561, 1826, 1978, 2871, 3259, 5309] | R29: y[(k_row.Type, j, t)] <= kendaraan.loc[k_row.Index, 'Volume'] * x[(k_row.Type, j, t)], | T29: if z[(k_row.Type, i)].X > 0.5: # Jika kendaraan ke-i dipakai
J30: for k_row in kendaraan.itertuples():
A31: } | R31: name=f"kapasitas_{k_row.Type}_{j}_trip{t}" | T31: total_kendaraan += 1
J32: for i in range(1, 20): # Anggap maksimal 5 kendaraan per jenis
A33: tujuan = pd.DataFrame(tujuan_data) | R33: ) | T33: if k_row.Type not in kendaraan_digunakan:
J34: obj += biaya_kendaraan[k_row.Type] * z[(k_row.Type, i)] # Biaya tetap penambahan kendaraan
A35: b. Data Kendaraan: | R35: c. Batasan Kapasitas Gudang per Trip: | T35: kendaraan_digunakan[k_row.Type] = 1
J36: m.setObjective(obj, GRB.MINIMIZE)
A37: Data ini berisi informasi mengenai kendaraan yang tersedia untuk pengiriman: | R37: Jumlah barang yang dikirim dalam satu trip tidak boleh melebihi kapasitas gudang. | T37: else:
J38: Biaya BBM dihitung berdasarkan formula:
A39: Type: Jenis kendaraan (misalnya CDD, CDE, dll.). | R39: for t in range(MAX_TRIPS): | T39: kendaraan_digunakan[k_row.Type] += 1
A40: Volume: Kapasitas kendaraan dalam jumlah barang yang dapat diangkut (per trip). | J40: Biaya per trip=2×(JarakKonsumsi)×Harga BBM\text{Biaya per trip} = 2 \times \left( \frac{\text{Jarak}}{\text{Konsumsi}} \right) \times \text{Harga BBM}
A41: BBM: Jenis bahan bakar yang digunakan oleh kendaraan (misalnya biosolar atau pertalite). | R41: m.addConstr( | T41: print("\nTotal Kendaraan yang Digunakan:", total_kendaraan)
A42: Cons: Konsumsi bahan bakar kendaraan per kilometer (liter/km). | J42: Ini untuk mengakomodasi perjalanan pulang-pergi.
...

Sheet Jumlah Trip Maksimal
A1: Distributor Area | B1: Area | C1: Type | D1: Waktu TRIP(jarak terjauh dibagi 45 km/hour) | E1: MaxTrip | F1: Waktu Tersedia | G1: Total waktu<waktu tersedia | K1: DC ID | L1: Area | M1: Type | N1: Capacity Kendaraan | O1: Waktu Trip Terjauh | P1: Maximum Trip | Q1: Waktu Tersedia
A2: Bali Nusra | B2: Denpasar | C2: Direct CPU | E2: =FLOOR(F2/D2,1) -> #DIV/0! | F2: =26*8 -> 208 | G2: =if(E2*D2<F2,True) -> #DIV/0! | I2: Jumlah Paket Trip | K2: DC031 | L2: Denpasar | M2: Direct CPU | N2: 5280 | O2: - | P2: - | Q2: =26*8 -> 208
A3: Bali Nusra | B3: Lombok | C3: Direct CPU | D3: =1046.393/45 -> 23.253178 | E3: =FLOOR(F3/D3,1) -> 8 | F3: =26*8 -> 208 | G3: =if(E3*D3<F3,True) -> TRUE | I3: =COUNT(D3,D9,D10,D12,D13,D14,D16,D18,D19,D20,D21,D24,D27,D28) -> 14 | K3: DC032 | L3: Kendari | M3: Direct CPU | N3: 1640 | O3: =275.58/45 -> 6.124 | P3: =FLOOR(Q3/O3,1) -> 33 | Q3: =26*8 -> 208
A4: Bali Nusra | B4: BIMA | C4: Indirect DC | E4: =FLOOR(F4/D4,1) -> #DIV/0! | F4: =26*8 -> 208 | G4: =if(E4*D4<F4,True) -> #DIV/0! | K4: DC033 | L4: Lombok | M4: Direct CPU | N4: 1600 | O4: =1046.393/45 -> 23.253178 | P4: 8 | Q4: =26*8 -> 208
A5: Bali Nusra | B5: Kupang | C5: Indirect DC | E5: =FLOOR(F5/D5,1) -> #DIV/0! | F5: =26*8 -> 208 | G5: =if(E5*D5<F5,True) -> #DIV/0! | K5: DC034 | L5: Makassar | M5: Direct CPU | N5: 2920 | O5: =357.38/45 -> 7.9417778 | P5: 26 | Q5: =26*8 -> 208
A6: Bali Nusra | B6: Maumere | C6: Indirect DC | E6: =FLOOR(F6/D6,1) -> #DIV/0! | F6: =26*8 -> 208 | G6: =if(E6*D6<F6,True) -> #DIV/0! | K6: DC035 | L6: Manado | M6: Direct CPU | N6: 3400 | O6: =396.91/45 -> 8.8202222 | P6: =FLOOR(Q6/O6,1) -> 23 | Q6: =26*8 -> 208
A7: Bali Nusra | B7: Sumbawa | C7: Indirect DC | E7: =FLOOR(F7/D7,1) -> #DIV/0! | F7: =26*8 -> 208 | G7: =if(E7*D7<F7,True) -> #DIV/0! | K7: DC036 | L7: Palu | M7: Direct CPU | N7: 1560 | O7: =589.5/45 -> 13.1 | P7: =FLOOR(Q7/O7,1) -> 15 | Q7: =26*8 -> 208
A8: Kalimantan | B8: Sintang | C8: Depo | E8: =FLOOR(F8/D8,1) -> #DIV/0! | F8: =26*8 -> 208 | G8: =if(E8*D8<F8,True) -> #DIV/0! | K8: DC037 | L8: Balikpapan | M8: Direct DC | N8: 2880 | O8: =161.958/45 -> 3.5990667 | P8: =FLOOR(208/O8,1) -> 57 | Q8: =26*8 -> 208
A9: Kalimantan | B9: Balikpapan | C9: Direct DC | D9: =161.958/45 -> 3.5990667 | E9: =FLOOR(208/D9,1) -> 57 | F9: =26*8 -> 208 | G9: =if(E9*D9<F9,True) -> TRUE | K9: DC038 | L9: Banjarmasin | M9: Direct DC | N9: 5280 | O9: =203.111/45 -> 4.5135778 | P9: =FLOOR(208/O9,1) -> 46 | Q9: =26*8 -> 208
A10: Kalimantan | B10: Banjarmasin | C10: Direct DC | D10: =203.111/45 -> 4.5135778 | E10: =FLOOR(208/D10,1) -> 46 | F10: =26*8 -> 208 | G10: =if(E10*D10<F10,True) -> TRUE | K10: DC039 | L10: Berau | M10: Direct DC | N10: 520 | O10: - | P10: - | Q10: =26*8 -> 208
A11: Kalimantan | B11: Berau | C11: Direct DC | E11: =FLOOR(208/D11,1) -> #DIV/0! | F11: =26*8 -> 208 | G11: =if(E11*D11<F11,True) -> #DIV/0! | K11: DC040 | L11: Bontang | M11: Direct DC | N11: 5280 | O11: =59.2/45 -> 1.3155556 | P11: =FLOOR(208/O11,1) -> 158 | Q11: =26*8 -> 208
A12: Kalimantan | B12: Bontang | C12: Direct DC | D12: =59.2/45 -> 1.3155556 | E12: =FLOOR(208/D12,1) -> 158 | F12: =26*8 -> 208 | G12: =if(E12*D12<F12,True) -> TRUE | K12: DC041 | L12: Palangkaraya | M12: Direct DC | N12: 1040 | O12: =343.092/45 -> 7.6242667 | P12: =FLOOR(208/O12,1) -> 27 | Q12: =26*8 -> 208
A13: Kalimantan | B13: Palangkaraya | C13: Direct DC | D13: =343.092/45 -> 7.6242667 | E13: =FLOOR(208/D13,1) -> 27 | F13: =26*8 -> 208 | G13: =if(E13*D13<F13,True) -> TRUE | K13: DC042 | L13: Pontianak | M13: Direct DC | N13: 5280 | O13: =352.4/45 -> 7.8311111 | P13: =FLOOR(208/O13,1) -> 26 | Q13: =26*8 -> 208
A14: Kalimantan | B14: Pontianak | C14: Direct DC | D14: =352.4/45 -> 7.8311111 | E14: =FLOOR(208/D14,1) -> 26 | F14: =26*8 -> 208 | G14: =if(E14*D14<F14,True) -> TRUE | K14: DC043 | L14: Samarinda | M14: Direct DC | N14: 1800 | O14: - | P14: - | Q14: =26*8 -> 208
A15: Kalimantan | B15: Samarinda | C15: Direct DC | E15: =FLOOR(208/D15,1) -> #DIV/0! | F15: =26*8 -> 208 | G15: =if(E15*D15<F15,True) -> #DIV/0! | K15: DC044 | L15: Sampit | M15: Direct DC | N15: 1000 | O15: =212.077/45 -> 4.7128222 | P15: =FLOOR(208/O15,1) -> 44 | Q15: =26*8 -> 208
A16: Kalimantan | B16: Sampit | C16: Direct DC | D16: =212.077/45 -> 4.7128222 | E16: =FLOOR(208/D16,1) -> 44 | F16: =26*8 -> 208 | G16: =if(E16*D16<F16,True) -> TRUE | K16: DC045 | L16: Tarakan | M16: Direct DC | N16: 520 | O16: - | P16: - | Q16: =26*8 -> 208
A17: Kalimantan | B17: Tarakan | C17: Direct DC | E17: =FLOOR(208/D17,1) -> #DIV/0! | F17: =26*8 -> 208 | G17: =if(E17*D17<F17,True) -> #DIV/0! | K17: DC046 | L17: Bau-Bau | M17: Indirect DC | N17: 200 | O17: - | P17: - | Q17: =26*8 -> 208
A18: Sulawesi | B18: Kendari | C18: Direct CPU | D18: =275.58/45 -> 6.124 | E18: =FLOOR(F18/D18,1) -> 33 | F18: =26*8 -> 208 | G18: =if(E18*D18<F18,True) -> TRUE | K18: DC047 | L18: BIMA | M18: Indirect DC | N18: 400 | O18: - | P18: - | Q18: =26*8 -> 208
A19: Sulawesi | B19: Makassar | C19: Direct CPU | D19: =357.38/45 -> 7.9417778 | E19: 26 | F19: =26*8 -> 208 | G19: =if(E19*D19<F19,True) -> TRUE | K19: DC048 | L19: Bone | M19: Indirect DC | N19: 600 | O19: - | P19: - | Q19: =26*8 -> 208
A20: Sulawesi | B20: Manado | C20: Direct CPU | D20: =396.91/45 -> 8.8202222 | E20: =FLOOR(F20/D20,1) -> 23 | F20: =26*8 -> 208 | G20: =if(E20*D20<F20,True) -> TRUE | K20: DC049 | L20: Gorontalo | M20: Indirect DC | N20: 1120 | O20: =134.66/45 -> 2.9924444 | P20: =FLOOR(Q20/O20,1) -> 69 | Q20: =26*8 -> 208
A21: Sulawesi | B21: Palu | C21: Direct CPU | D21: =589.5/45 -> 13.1 | E21: =FLOOR(F21/D21,1) -> 15 | F21: =26*8 -> 208 | G21: =if(E21*D21<F21,True) -> TRUE | K21: DC050 | L21: Kupang | M21: Indirect DC | N21: 1240 | O21: - | P21: - | Q21: =26*8 -> 208
A22: Sulawesi | B22: Bau-Bau | C22: Indirect DC | E22: =FLOOR(F22/D22,1) -> #DIV/0! | F22: =26*8 -> 208 | G22: =if(E22*D22<F22,True) -> #DIV/0! | K22: DC051 | L22: Luwuk | M22: Indirect DC | N22: 320 | O22: - | P22: - | Q22: =26*8 -> 208
A23: Sulawesi | B23: Bone | C23: Indirect DC | E23: =FLOOR(F23/D23,1) -> #DIV/0! | F23: =26*8 -> 208 | G23: =if(E23*D23<F23,True) -> #DIV/0! | K23: DC052 | L23: Mamuju | M23: Indirect DC | N23: 400 | O23: - | P23: - | Q23: =26*8 -> 208
A24: Sulawesi | B24: Gorontalo | C24: Indirect DC | D24: =134.66/45 -> 2.9924444 | E24: =FLOOR(F24/D24,1) -> 69 | F24: =26*8 -> 208 | G24: =if(E24*D24<F24,True) -> TRUE | K24: DC053 | L24: Maumere | M24: Indirect DC | N24: 960 | O24: - | P24: - | Q24: =26*8 -> 208
A25: Sulawesi | B25: Luwuk | C25: Indirect DC | E25: =FLOOR(F25/D25,1) -> #DIV/0! | F25: =26*8 -> 208 | G25: =if(E25*D25<F25,True) -> #DIV/0! | K25: DC054 | L25: Palopo | M25: Indirect DC | N25: 1640 | O25: =138.45/45 -> 3.0766667 | P25: =FLOOR(Q25/O25,1) -> 67 | Q25: =26*8 -> 208
A26: Sulawesi | B26: Mamuju | C26: Indirect DC | E26: =FLOOR(F26/D26,1) -> #DIV/0! | F26: =26*8 -> 208 | G26: =if(E26*D26<F26,True) -> #DIV/0! | K26: DC055 | L26: Pare-Pare | M26: Indirect DC | N26: 1480 | O26: =103.54/45 -> 2.3008889 | P26: =FLOOR(Q26/O26,1) -> 90 | Q26: =26*8 -> 208
A27: Sulawesi | B27: Palopo | C27: Indirect DC | D27: =138.45/45 -> 3.0766667 | E27: =FLOOR(F27/D27,1) -> 67 | F27: =26*8 -> 208 | G27: =if(E27*D27<F27,True) -> TRUE | K27: DC056 | L27: Poso | M27: Indirect DC | N27: 800 | O27: - | P27: - | Q27: =26*8 -> 208
A28: Sulawesi | B28: Pare-Pare | C28: Indirect DC | D28: =103.54/45 -> 2.3008889 | E28: =FLOOR(F28/D28,1) -> 90 | F28: =26*8 -> 208 | G28: =if(E28*D28<F28,True) -> TRUE | K28: DC057 | L28: Sumbawa | M28: Indirect DC | N28: 320 | O28: - | P28: - | Q28: =26*8 -> 208
A29: Sulawesi | B29: Poso | C29: Indirect DC | E29: =FLOOR(F29/D29,1) -> #DIV/0! | F29: =26*8 -> 208 | G29: =if(E29*D29<F29,True) -> #DIV/0! | Q29: =26*8 -> 208

Sheet (SRP Usulan) Jarak Tempuh Middl
A1: ID Asal | B1: Nama Kota | C1: Id Tujuan | D1: Nama Kota Tujuan | E1: Jarak(KM)
A2: DC037 | B2: Balikpapan | C2: DC020 | D2: Penajam-Grogot | E2: 161.958 | F2: =E2*2 -> 323.916 | G2: =F2/45 -> 7.1981333 | H2: =ROUNDUP(G2/(8*30),0) -> 1 | I2: =G2/L2 -> 0.044988333 | J2: =ROUNDUP(I2/L3,0) -> 1 | K2: jam kerja= | L2: 160 | N2: ID Asal | O2: Nama Kota | P2: Id Tujuan | Q2: Nama Kota Tujuan | R2: Jarak(KM) | T2: ID Asal | U2: Lokasi Asal | V2: ID Tujuan | W2: Nama Kota | X2: Jarak (km)
A3: DC038 | B3: Banjarmasin | C3: DC003 | D3: Barabai | E3: 144.846 | F3: =E3*2 -> 289.692 | G3: =F3/45 -> 6.4376 | H3: =ROUNDUP(G3/(8*30),0) -> 1 | K3: trip/bulan | L3: 10 | N3: DC041 | O3: Palangkaraya | P3: DC001 | Q3: Ampah | R3: 343.092 | T3: DC037 | U3: Balikpapan | V3: DC039 | W3: Penajam-Grogot | X3: 161958
A4: DC038 | B4: Banjarmasin | C4: DC005 | D4: Batulicin | E4: 203.111 | F4: =E4*2 -> 406.222 | G4: =F4/45 -> 9.0271556 | H4: =ROUNDUP(G4/(8*30),0) -> 1 | N4: DC033 | O4: Manado | P4: DC002 | Q4: Amurang | R4: 55.4 | T4: DC038 | U4: Banjarmasin | V4: DC037 | W4: Barabai | X4: 144846
A5: DC038 | B5: Banjarmasin | C5: DC022 | D5: Rantau | E5: 94.264 | F5: =E5*2 -> 188.528 | G5: =F5/45 -> 4.1895111 | H5: =ROUNDUP(G5/(8*30),0) -> 1 | N5: DC038 | O5: Banjarmasin | P5: DC003 | Q5: Barabai | R5: 144.846 | T5: DC038 | U5: Banjarmasin | V5: DC037 | W5: Batulicin | X5: 203111
A6: DC040 | B6: Bontang | C6: DC008 | D6: Bontang-Sangata | E6: 59.2 | F6: =E6*2 -> 118.4 | G6: =F6/45 -> 2.6311111 | H6: =ROUNDUP(G6/(8*30),0) -> 1 | N6: DC047 | O6: Pare-Pare | P6: DC004 | Q6: Barru | R6: 62.41 | T6: DC038 | U6: Banjarmasin | V6: DC037 | W6: Rantau | X6: 94264
A7: DC049 | B7: Gorontalo | C7: DC016 | D7: Marissa | E7: 134.66 | F7: =E7*2 -> 269.32 | G7: =F7/45 -> 5.9848889 | H7: =ROUNDUP(G7/(8*30),0) -> 1 | N7: DC038 | O7: Banjarmasin | P7: DC005 | Q7: Batulicin | R7: 203.111 | T7: DC040 | U7: Bontang | V7: DC045 | W7: Bontang-Sangata | X7: 59.2
A8: DC035 | B8: Kendari | C8: DC013 | D8: Kolaka | E8: 154.22 | N8: DC046 | O8: Palopo | P8: DC006 | Q8: Belopa | R8: 49.98 | T8: DC034 | U8: Lombok | V8: DC054 | W8: BIMA | X8: 440971
A9: DC035 | B9: Kendari | C9: DC030 | D9: Unaaha | E9: 13.78 | N9: DC033 | O9: Manado | P9: DC007 | Q9: Bitung | R9: 47.8 | T9: DC048 | U9: Gorontalo | V9: DC018 | W9: Marissa | X9: 134.66
A10: DC035 | B10: Kendari | C10: DC046 | D10: Bau Bau | E10: 275.58 | N10: DC040 | O10: Bontang | P10: DC008 | Q10: Bontang-Sangata | R10: 59.2 | T10: PabrikKarawang | U10: Karawang | V10: DC031 | W10: Denpasar | X10: 1044466
A11: DC034 | B11: Lombok | C11: DC047 | D11: BIMA | E11: 440.971 | F11: =COUNT(Table1[Jarak(KM)]) -> 42 | N11: DC031 | O11: Makassar | P11: DC009 | Q11: Bulukumba | R11: 200 | T11: PabrikKarawang | U11: Karawang | V11: DC034 | W11: Lombok | X11: 1144628
A12: DC034 | B12: Lombok | C12: DC050 | D12: Kupang | E12: 1046.393 | N12: DC031 | O12: Makassar | P12: DC010 | Q12: Gowa | R12: 16.37 | T12: DC035 | U12: Kendari | V12: DC053 | W12: Bau Bau | X12: 275.58
A13: DC034 | B13: Lombok | C13: DC053 | D13: Maumere | E13: 924.619 | N13: DC031 | O13: Makassar | P13: DC011 | Q13: Jeneponto | R13: 97.42 | T13: DC035 | U13: Kendari | V13: DC015 | W13: Kolaka | X13: 154.22
A14: DC034 | B14: Lombok | C14: DC057 | D14: Sumbawa | E14: 179.485 | N14: DC042 | O14: Pontianak | P14: DC012 | Q14: Ketapang | R14: 352.4 | T14: DC035 | U14: Kendari | V14: DC030 | W14: Unaaha | X14: 13.78
A15: DC031 | B15: Makassar | C15: DC009 | D15: Bulukumba | E15: 200 | N15: DC035 | O15: Kendari | P15: DC013 | Q15: Kolaka | R15: 154.22 | T15: DC034 | U15: Lombok | V15: DC049 | W15: Kupang | X15: 1046393
A16: DC031 | B16: Makassar | C16: DC010 | D16: Gowa | E16: 16.37 | N16: DC033 | O16: Manado | P16: DC014 | Q16: Kotamobagu | R16: 170.45 | T16: DC034 | U16: Lombok | V16: DC051 | W16: Maumere | X16: 924619
A17: DC031 | B17: Makassar | C17: DC011 | D17: Jeneponto | E17: 97.42 | N17: DC046 | O17: Palopo | P17: DC015 | Q17: Mangkutana | R17: 138.45 | T17: DC034 | U17: Lombok | V17: DC056 | W17: Sumbawa | X17: 179485
A18: DC031 | B18: Makassar | C18: DC018 | D18: Pangkep | E18: 55.23 | N18: DC048 | O18: Gorontalo | P18: DC016 | Q18: Marissa | R18: 134.66 | T18: DC031 | U18: Makassar | V18: DC050 | W18: Bone | X18: 194.85
A19: DC034 | B19: Makassar | C19: DC025 | D19: Sinjai | E19: 224.38 | N19: DC044 | O19: Sampit | P19: DC017 | Q19: Pangkalanbun | R19: 212.077 | T19: DC031 | U19: Makassar | V19: DC012 | W19: Bulukumba | X19: 200
A20: DC031 | B20: Makassar | C20: DC027 | D20: Takalar | E20: 41.33 | N20: DC031 | O20: Makassar | P20: DC018 | Q20: Pangkep | R20: 55.23 | T20: DC031 | U20: Makassar | V20: DC013 | W20: Gowa | X20: 16.37
A21: DC031 | B21: Makassar | C21: DC048 | D21: Bone | E21: 194.85 | N21: DC036 | O21: Palu | P21: DC019 | Q21: Parigi | R21: 71.72 | T21: DC031 | U21: Makassar | V21: DC014 | W21: Jeneponto | X21: 97.42
A22: DC031 | B22: Makassar | C22: DC054 | D22: Palopo | E22: 375.38 | N22: DC037 | O22: Balikpapan | P22: DC020 | Q22: Penajam-Grogot | R22: 161.958 | T22: DC031 | U22: Makassar | V22: DC046 | W22: Palopo | X22: 375.38
A23: DC031 | B23: Makassar | C23: DC055 | D23: Pare-Pare | E23: 162.64 | N23: DC047 | O23: Pare-Pare | P23: DC021 | Q23: Polman | R23: 103.54 | T23: DC031 | U23: Makassar | V23: DC020 | W23: Pangkep | X23: 55.23
... A31: DC054 | B31: Palopo | C31: DC015 | D31: Mangkutana | E31: 138.45 | N31: DC046 | O31: Palopo | P31: DC029 | Q31: Toraja | R31: 72.18 | T31: DC046 | U31: Palopo | V31: DC009 | W31: Belopa | X31: 49.98
A32: DC054 | B32: Palopo | C32: DC029 | D32: Toraja | E32: 72.18 | H32: PabrikKarawang | I32: Karawang | J32: DC031 | K32: Denpasar | L32: 1044.466 | N32: DC035 | O32: Kendari | P32: DC030 | Q32: Unaaha | R32: 13.78 | T32: DC046 | U32: Palopo | V32: DC029 | W32: Toraja | X32: 72.18
A33: DC036 | B33: Palu | C33: DC019 | D33: Parigi | E33: 71.72 | H33: PabrikKarawang | I33: Karawang | J33: DC034 | K33: Lombok | L33: 1144.628 | N33: DC035 | O33: Kendari | P33: DC046 | Q33: Bau Bau | R33: 275.58 | T33: DC046 | U33: Palopo | V33: DC017 | W33: Mangkutana | X33: 138.45
A34: DC036 | B34: Palu | C34: DC051 | D34: Luwuk | E34: 589.5 | N34: DC031 | O34: Makassar | P34: DC047 | Q34: Pare-Pare | R34: 162.64 | T34: DC036 | U34: Palu | V34: DC055 | W34: Luwuk | X34: 589.5
A35: DC036 | B35: Palu | C35: DC052 | D35: Mamuju | E35: 406.82 | N35: DC034 | O35: Lombok | P35: DC047 | Q35: BIMA | R35: 440.971 | T35: DC036 | U35: Palu | V35: DC057 | W35: Mamuju | X35: 406.82
A36: DC036 | B36: Palu | C36: DC056 | D36: Poso | E36: 206.67 | N36: DC031 | O36: Makassar | P36: DC048 | Q36: Bone | R36: 194.85 | T36: DC036 | U36: Palu | V36: DC021 | W36: Parigi | X36: 71.72
A37: DC047 | B37: Pare-Pare | C37: DC004 | D37: Barru | E37: 62.41 | N37: DC033 | O37: Manado | P37: DC048 | Q37: Gorontalo | R37: 396.91 | T37: DC036 | U37: Palu | V37: DC052 | W37: Poso | X37: 206.67
A38: DC047 | B38: Pare-Pare | C38: DC021 | D38: Polman | E38: 103.54 | N38: DC033 | O38: Manado | P38: DC049 | Q38: Gorontalo | R38: 396.91 | T38: DC047 | U38: Pare-Pare | V38: DC007 | W38: Barru | X38: 62.41
A39: DC047 | B39: Pare-Pare | C39: DC023 | D39: Sengkang | E39: 80.4 | N39: DC034 | O39: Lombok | P39: DC050 | Q39: Kupang | R39: 1046.393 | T39: DC047 | U39: Pare-Pare | V39: DC023 | W39: Polman | X39: 103.54
A40: DC042 | B40: Pontianak | C40: DC012 | D40: Ketapang | E40: 352.4 | N40: DC036 | O40: Palu | P40: DC051 | Q40: Luwuk | R40: 589.5 | T40: DC047 | U40: Pare-Pare | V40: DC025 | W40: Sengkang | X40: 80.4
A41: DC042 | B41: Pontianak | C41: DC024 | D41: Singkawang | E41: 151 | N41: DC036 | O41: Palu | P41: DC052 | Q41: Mamuju | R41: 406.82 | T41: DC042 | U41: Pontianak | V41: DC041 | W41: Singkawang | X41: 151
A42: DC042 | B42: Pontianak | C42: DC026 | D42: Sintang | E42: 321 | N42: DC034 | O42: Lombok | P42: DC053 | Q42: Maumere | R42: 924.619 | T42: DC042 | U42: Pontianak | V42: DC012 | W42: Ketapang | X42: 352.4
A43: DC044 | B43: Sampit | C43: DC017 | D43: Pangkalanbun | E43: 212.077 | N43: DC031 | O43: Makassar | P43: DC054 | Q43: Palopo | R43: 375.38 | T43: DC044 | U43: Pontianak | V43: DC026 | W43: Sintang | X43: 321
N44: DC031 | O44: Makassar | P44: DC055 | Q44: Pare-Pare | R44: 162.64 | T44: DC044 | U44: Sampit | V44: DC040 | W44: Pangkalanbun | X44: 212077
N45: DC036 | O45: Palu | P45: DC056 | Q45: Poso | R45: 206.67 | T45: DC033 | U45: Manado | V45: DC048 | W45: Gorontalo | X45: 396.91
N46: DC034 | O46: Lombok | P46: DC057 | Q46: Sumbawa | R46: 179.485 | T46: DC031 | U46: Makassar | V46: DC047 | W46: Pare-Pare | X46: 162.64

Sheet (agoy fadli) Total Permintaan M
A1: Permintaan | B1: Area | C1: DC ID | D1: Type | F1: ID Asal | G1: Nama Kota | H1: Id Tujuan | I1: Nama Kota Tujuan | J1: Jarak(KM) | L1: ID Asal | M1: Nama Kota | N1: Id Tujuan | O1: Nama Kota Tujuan | P1: Jarak(KM) | R1: ID Asal | S1: Lokasi Asal | T1: ID Tujuan | U1: Nama Kota | V1: Jarak (km)
A2: =ROUNDUP(4623,0) -> 4623 | B2: Ampah - Teweh | C2: DC001 | D2: Depo | F2: DC041 | G2: Palangkaraya | H2: DC001 | I2: Ampah | J2: 343.092 | L2: DC041 | M2: Palangkaraya | N2: DC001 | O2: Ampah | P2: 343.092 | R2: DC037 | S2: Balikpapan | T2: DC039 | U2: Penajam-Grogot | V2: 161958
A3: =ROUNDUP(1729,0) -> 1729 | B3: Amurang | C3: DC002 | D3: Depo | F3: DC033 | G3: Manado | H3: DC002 | I3: Amurang | J3: 55.4 | L3: DC033 | M3: Manado | N3: DC002 | O3: Amurang | P3: 55.4 | R3: DC038 | S3: Banjarmasin | T3: DC037 | U3: Barabai | V3: 144846
A4: 12496 | B4: Barabai | C4: DC003 | D4: Depo | F4: DC038 | G4: Banjarmasin | H4: DC003 | I4: Barabai | J4: 144.846 | L4: DC038 | M4: Banjarmasin | N4: DC003 | O4: Barabai | P4: 144.846 | R4: DC038 | S4: Banjarmasin | T4: DC037 | U4: Batulicin | V4: 203111
A5: 967 | B5: Barru | C5: DC004 | D5: Depo | F5: DC047 | G5: Pare-Pare | H5: DC004 | I5: Barru | J5: 62.41 | L5: DC047 | M5: Pare-Pare | N5: DC004 | O5: Barru | P5: 62.41 | R5: DC038 | S5: Banjarmasin | T5: DC037 | U5: Rantau | V5: 94264
A6: 7766 | B6: Batulicin | C6: DC005 | D6: Depo | F6: DC038 | G6: Banjarmasin | H6: DC005 | I6: Batulicin | J6: 203.111 | L6: DC038 | M6: Banjarmasin | N6: DC005 | O6: Batulicin | P6: 203.111 | R6: DC040 | S6: Bontang | T6: DC045 | U6: Bontang-Sangata | V6: 59.2
A7: 1924 | B7: Belopa | C7: DC006 | D7: Depo | F7: DC054 | G7: Palopo | H7: DC006 | I7: Belopa | J7: 49.98 | L7: DC046 | M7: Palopo | N7: DC006 | O7: Belopa | P7: 49.98 | R7: DC034 | S7: Lombok | T7: DC054 | U7: BIMA | V7: 440971
A8: 2269 | B8: Bitung | C8: DC007 | D8: Depo | F8: DC033 | G8: Manado | H8: DC007 | I8: Bitung | J8: 47.8 | L8: DC033 | M8: Manado | N8: DC007 | O8: Bitung | P8: 47.8 | R8: DC048 | S8: Gorontalo | T8: DC018 | U8: Marissa | V8: 134.66
A9: 1330 | B9: Bontang-Sangata | C9: DC008 | D9: Depo | F9: DC040 | G9: Bontang | H9: DC008 | I9: Bontang-Sangata | J9: 59.2 | L9: DC040 | M9: Bontang | N9: DC008 | O9: Bontang-Sangata | P9: 59.2 | R9: PabrikKarawang | S9: Karawang | T9: DC031 | U9: Denpasar | V9: 1044466
A10: 2549 | B10: Bulukumba | C10: DC009 | D10: Depo | F10: DC031 | G10: Makassar | H10: DC009 | I10: Bulukumba | J10: 200 | L10: DC031 | M10: Makassar | N10: DC009 | O10: Bulukumba | P10: 200 | R10: PabrikKarawang | S10: Karawang | T10: DC034 | U10: Lombok | V10: 1144628
A11: 11369 | B11: Gowa | C11: DC010 | D11: Depo | F11: DC031 | G11: Makassar | H11: DC010 | I11: Gowa | J11: 16.37 | L11: DC031 | M11: Makassar | N11: DC010 | O11: Gowa | P11: 16.37 | R11: DC035 | S11: Kendari | T11: DC053 | U11: Bau Bau | V11: 275.58
A12: 2561 | B12: Jeneponto | C12: DC011 | D12: Depo | F12: DC031 | G12: Makassar | H12: DC011 | I12: Jeneponto | J12: 97.42 | L12: DC031 | M12: Makassar | N12: DC011 | O12: Jeneponto | P12: 97.42 | R12: DC035 | S12: Kendari | T12: DC015 | U12: Kolaka | V12: 154.22
A13: =3105+208 -> 3313 | B13: Ketapang | C13: DC012 | D13: Depo | F13: DC042 | G13: Pontianak | H13: DC012 | I13: Ketapang | J13: 352.4 | L13: DC042 | M13: Pontianak | N13: DC012 | O13: Ketapang | P13: 352.4 | R13: DC035 | S13: Kendari | T13: DC030 | U13: Unaaha | V13: 13.78
A14: 3579 | B14: Kolaka | C14: DC013 | D14: Depo | F14: DC035 | G14: Kendari | H14: DC013 | I14: Kolaka | J14: 154.22 | L14: DC035 | M14: Kendari | N14: DC013 | O14: Kolaka | P14: 154.22 | R14: DC034 | S14: Lombok | T14: DC049 | U14: Kupang | V14: 1046393
A15: 3692 | B15: Kotamobagu | C15: DC014 | D15: Depo | F15: DC033 | G15: Manado | H15: DC014 | I15: Kotamobagu | J15: 170.45 | L15: DC033 | M15: Manado | N15: DC014 | O15: Kotamobagu | P15: 170.45 | R15: DC034 | S15: Lombok | T15: DC051 | U15: Maumere | V15: 924619
A16: 4425 | B16: Mangkutana | C16: DC015 | D16: Depo | F16: DC054 | G16: Palopo | H16: DC015 | I16: Mangkutana | J16: 138.45 | L16: DC046 | M16: Palopo | N16: DC015 | O16: Mangkutana | P16: 138.45 | R16: DC034 | S16: Lombok | T16: DC056 | U16: Sumbawa | V16: 179485
A17: 2672 | B17: Marisa | C17: DC016 | D17: Depo | F17: DC049 | G17: Gorontalo | H17: DC016 | I17: Marissa | J17: 134.66 | L17: DC048 | M17: Gorontalo | N17: DC016 | O17: Marissa | P17: 134.66 | R17: DC031 | S17: Makassar | T17: DC050 | U17: Bone | V17: 194.85
A18: 6285 | B18: Pangkalanbun | C18: DC017 | D18: Depo | F18: DC044 | G18: Sampit | H18: DC017 | I18: Pangkalanbun | J18: 212.077 | L18: DC044 | M18: Sampit | N18: DC017 | O18: Pangkalanbun | P18: 212.077 | R18: DC031 | S18: Makassar | T18: DC012 | U18: Bulukumba | V18: 200
A19: 1826 | B19: Pangkep | C19: DC018 | D19: Depo | F19: DC031 | G19: Makassar | H19: DC018 | I19: Pangkep | J19: 55.23 | L19: DC031 | M19: Makassar | N19: DC018 | O19: Pangkep | P19: 55.23 | R19: DC031 | S19: Makassar | T19: DC013 | U19: Gowa | V19: 16.37
A20: 1223 | B20: Parigi | C20: DC019 | D20: Depo | F20: DC036 | G20: Palu | H20: DC019 | I20: Parigi | J20: 71.72 | L20: DC036 | M20: Palu | N20: DC019 | O20: Parigi | P20: 71.72 | R20: DC031 | S20: Makassar | T20: DC014 | U20: Jeneponto | V20: 97.42
A21: 4675 | B21: Penajam-Grogot | C21: DC020 | D21: Depo | F21: DC037 | G21: Balikpapan | H21: DC020 | I21: Penajam-Grogot | J21: 161.958 | L21: DC037 | M21: Balikpapan | N21: DC020 | O21: Penajam-Grogot | P21: 161.958 | R21: DC031 | S21: Makassar | T21: DC046 | U21: Palopo | V21: 375.38
A22: 3422 | B22: Polman | C22: DC021 | D22: Depo | F22: DC047 | G22: Pare-Pare | H22: DC021 | I22: Polman | J22: 103.54 | L22: DC047 | M22: Pare-Pare | N22: DC021 | O22: Polman | P22: 103.54 | R22: DC031 | S22: Makassar | T22: DC020 | U22: Pangkep | V22: 55.23
A23: 4287 | B23: Rantau | C23: DC022 | D23: Depo | F23: DC038 | G23: Banjarmasin | H23: DC022 | I23: Rantau | J23: 94.264 | L23: DC038 | M23: Banjarmasin | N23: DC022 | O23: Rantau | P23: 94.264 | R23: DC031 | S23: Makassar | T23: DC027 | U23: Takalar | V23: 41.33
A24: 3554 | B24: Sengkang | C24: DC023 | D24: Depo | F24: DC047 | G24: Pare-Pare | H24: DC023 | I24: Sengkang | J24: 80.4 | L24: DC047 | M24: Pare-Pare | N24: DC023 | O24: Sengkang | P24: 80.4 | R24: DC047 | S24: Makassar | T24: DC026 | U24: Sinjai | V24: 224.38
A25: 3964 | B25: Singkawang | C25: DC024 | D25: Depo | F25: DC042 | G25: Pontianak | H25: DC024 | I25: Singkawang | J25: 151 | L25: DC042 | M25: Pontianak | N25: DC024 | O25: Singkawang | P25: 151 | R25: DC033 | S25: Manado | T25: DC005 | U25: Amurang | V25: 55.4
A26: 1169 | B26: Sinjai | C26: DC025 | D26: Depo | F26: DC034 | G26: Makassar | H26: DC025 | I26: Sinjai | J26: 224.38 | L26: DC047 | M26: Makassar | N26: DC025 | O26: Sinjai | P26: 224.38 | R26: DC033 | S26: Manado | T26: DC016 | U26: Kotamobagu | V26: 170.45
A27: =2842+3 -> 2845 | B27: Sintang | C27: DC026 | D27: Depo | F27: DC042 | G27: Pontianak | H27: DC026 | I27: Sintang | J27: 321 | L27: DC044 | M27: Pontianak | N27: DC026 | O27: Sintang | P27: 321 | R27: DC033 | S27: Manado | T27: DC028 | U27: Tomohon | V27: 35.19
A28: 1978 | B28: Takalar | C28: DC027 | D28: Depo | F28: DC031 | G28: Makassar | H28: DC027 | I28: Takalar | J28: 41.33 | L28: DC031 | M28: Makassar | N28: DC027 | O28: Takalar | P28: 41.33 | R28: DC033 | S28: Manado | T28: DC007 | U28: Bitung | V28: 47.8
A29: 2088 | B29: Tomohon | C29: DC028 | D29: Depo | F29: DC033 | G29: Manado | H29: DC028 | I29: Tomohon | J29: 35.19 | L29: DC033 | M29: Manado | N29: DC028 | O29: Tomohon | P29: 35.19 | R29: DC041 | S29: Palangkaraya | T29: DC001 | U29: Ampah | V29: 343092
A30: 3785 | B30: Toraja | C30: DC029 | D30: Depo | F30: DC054 | G30: Palopo | H30: DC029 | I30: Toraja | J30: 72.18 | L30: DC046 | M30: Palopo | N30: DC029 | O30: Toraja | P30: 72.18 | R30: DC046 | S30: Palopo | T30: DC009 | U30: Belopa | V30: 49.98
A31: 2181 | B31: Unaaha | C31: DC030 | D31: Depo | F31: DC035 | G31: Kendari | H31: DC030 | I31: Unaaha | J31: 13.78 | L31: DC035 | M31: Kendari | N31: DC030 | O31: Unaaha | P31: 13.78 | R31: DC046 | S31: Palopo | T31: DC029 | U31: Toraja | V31: 72.18
A32: 28496 | B32: Denpasar | C32: DC031 | D32: Direct CPU | F32: DC035 | G32: Kendari | H32: DC046 | I32: Bau Bau | J32: 275.58 | L32: DC035 | M32: Kendari | N32: DC046 | O32: Bau Bau | P32: 275.58 | R32: DC046 | S32: Palopo | T32: DC017 | U32: Mangkutana | V32: 138.45
A33: 6252 | B33: Kendari | C33: DC032 | D33: Direct CPU | F33: DC034 | G33: Lombok | H33: DC047 | I33: BIMA | J33: 440.971 | L33: DC031 | M33: Makassar | N33: DC047 | O33: Pare-Pare | P33: 162.64 | R33: DC036 | S33: Palu | T33: DC055 | U33: Luwuk | V33: 589.5
A34: 17216 | B34: Lombok | C34: DC033 | D34: Direct CPU | F34: DC031 | G34: Makassar | H34: DC048 | I34: Bone | J34: 194.85 | L34: DC034 | M34: Lombok | N34: DC047 | O34: BIMA | P34: 440.971 | R34: DC036 | S34: Palu | T34: DC057 | U34: Mamuju | V34: 406.82
A35: 8800 | B35: Makassar | C35: DC034 | D35: Direct CPU | F35: DC033 | G35: Manado | H35: DC049 | I35: Gorontalo | J35: 396.91 | L35: DC031 | M35: Makassar | N35: DC048 | O35: Bone | P35: 194.85 | R35: DC036 | S35: Palu | T35: DC021 | U35: Parigi | V35: 71.72
A36: 6680 | B36: Manado | C36: DC035 | D36: Direct CPU | F36: DC034 | G36: Lombok | H36: DC050 | I36: Kupang | J36: 1046.393 | L36: DC033 | M36: Manado | N36: DC048 | O36: Gorontalo | P36: 396.91 | R36: DC036 | S36: Palu | T36: DC052 | U36: Poso | V36: 206.67
A37: 7491 | B37: Palu | C37: DC036 | D37: Direct CPU | F37: DC036 | G37: Palu | H37: DC051 | I37: Luwuk | J37: 589.5 | L37: DC033 | M37: Manado | N37: DC049 | O37: Gorontalo | P37: 396.91 | R37: DC047 | S37: Pare-Pare | T37: DC007 | U37: Barru | V37: 62.41
A38: 16518 | B38: Balikpapan | C38: DC037 | D38: Direct DC | F38: DC036 | G38: Palu | H38: DC052 | I38: Mamuju | J38: 406.82 | L38: DC034 | M38: Lombok | N38: DC050 | O38: Kupang | P38: 1046.393 | R38: DC047 | S38: Pare-Pare | T38: DC023 | U38: Polman | V38: 103.54
A39: 22620 | B39: Banjarmasin | C39: DC038 | D39: Direct DC | F39: DC034 | G39: Lombok | H39: DC053 | I39: Maumere | J39: 924.619 | L39: DC036 | M39: Palu | N39: DC051 | O39: Luwuk | P39: 589.5 | R39: DC047 | S39: Pare-Pare | T39: DC025 | U39: Sengkang | V39: 80.4
... A43: 8377 | B43: Pontianak | C43: DC042 | D43: Direct DC | F43: DC034 | G43: Lombok | H43: DC057 | I43: Sumbawa | J43: 179.485 | L43: DC031 | M43: Makassar | N43: DC055 | O43: Pare-Pare | P43: 162.64 | R43: DC044 | S43: Sampit | T43: DC040 | U43: Pangkalanbun | V43: 212077
...

Sheet Sheet20
A1: Demand | B1: Daerah | C1: DC | D1: Tipe | E1: Total Pengiriman | F1: Minimal Kapasitas | G1: Kapasitas Kendaraan | H1: Cek | L1: Type | M1: Volume | N1: Harga BBM | O1: Petrol Consumption (Rasio BBM) | P1: Harga Bahan Bakar/KM
A2: 28496 | B2: Denpasar | C2: DC031 | D2: Direct CPU | E2: 18 | F2: =ROUNDUP(A2/E2,0) -> 1584 | G2: 5280 | H2: =IF(G2>F2,TRUE) -> TRUE | L2: CDD | M2: 280 | O2: 4 | P2: =6800/4 -> 1700
A3: 6252 | B3: Kendari | C3: DC032 | D3: Direct CPU | E3: 7 | F3: =ROUNDUP(A3/E3,0) -> 894 | G3: 1640 | H3: =IF(G3>F3,TRUE) -> TRUE | L3: CDE | M3: 200 | O3: 7 | P3: =6800/7 -> 971.42857
A4: 17216 | B4: Lombok | C4: DC033 | D4: Direct CPU | E4: 24 | F4: =ROUNDUP(A4/E4,0) -> 718 | G4: 1600 | H4: =IF(G4>F4,TRUE) -> TRUE | L4: GrandMax | M4: 120 | O4: 8 | P4: =10000/4 -> 2500
A5: 8800 | B5: Makassar | C5: DC034 | D5: Direct CPU | E5: 27 | F5: =ROUNDUP(A5/E5,0) -> 326 | G5: 2920 | H5: =IF(G5>F5,TRUE) -> TRUE | L5: Kijang | M5: 80 | O5: 10 | P5: =10000/10 -> 1000
A6: 6680 | B6: Manado | C6: DC035 | D6: Direct CPU | E6: 11 | F6: =ROUNDUP(A6/E6,0) -> 608 | G6: 3400 | H6: =IF(G6>F6,TRUE) -> TRUE | L6: Motorbike | M6: 5 | O6: 15 | P6: =10000/15 -> 666.66667
A7: 7491 | B7: Palu | C7: DC036 | D7: Direct CPU | E7: 10 | F7: =ROUNDUP(A7/E7,0) -> 750 | G7: 1560 | H7: =IF(G7>F7,TRUE) -> TRUE
A8: 16518 | B8: Balikpapan | C8: DC037 | D8: Direct DC | E8: 9 | F8: =ROUNDUP(A8/E8,0) -> 1836 | G8: 2880 | H8: =IF(G8>F8,TRUE) -> TRUE
A9: 22620 | B9: Banjarmasin | C9: DC038 | D9: Direct DC | E9: 20 | F9: =ROUNDUP(A9/E9,0) -> 1131 | G9: 5280 | H9: =IF(G9>F9,TRUE) -> TRUE | L9: Type | M9: Volume
A10: 2879 | B10: Berau | C10: DC039 | D10: Direct DC | E10: 3 | F10: =ROUNDUP(A10/E10,0) -> 960 | G10: 520 | H10: =IF(G10>F10,TRUE) -> FALSE | L10: 40FT | M10: 2360
A11: 2010 | B11: Bontang | C11: DC040 | D11: Direct DC | E11: 3 | F11: =ROUNDUP(A11/E11,0) -> 670 | G11: 5280 | H11: =IF(G11>F11,TRUE) -> TRUE | L11: Build Up | M11: 1600
A12: 4632 | B12: Palangkaraya | C12: DC041 | D12: Direct DC | E12: 4 | F12: =ROUNDUP(A12/E12,0) -> 1158 | G12: 1040 | H12: =IF(G12>F12,TRUE) -> FALSE | L12: 20FT | M12: 1160
A13: 8377 | B13: Pontianak | C13: DC042 | D13: Direct DC | E13: 8 | F13: =ROUNDUP(A13/E13,0) -> 1048 | G13: 5280 | H13: =IF(G13>F13,TRUE) -> TRUE | L13: FUSO | M13: 880
A14: 11295 | B14: Samarinda | C14: DC043 | D14: Direct DC | E14: 10 | F14: =ROUNDUP(A14/E14,0) -> 1130 | G14: 1800 | H14: =IF(G14>F14,TRUE) -> TRUE | L14: CDD | M14: 280
A15: 4316 | B15: Sampit | C15: DC044 | D15: Direct DC | E15: 5 | F15: =ROUNDUP(A15/E15,0) -> 864 | G15: 1000 | H15: =IF(G15>F15,TRUE) -> TRUE
A16: 12523 | B16: Tarakan | C16: DC045 | D16: Direct DC | E16: 6 | F16: =ROUNDUP(A16/E16,0) -> 2088 | G16: 520 | H16: =IF(G16>F16,TRUE) -> FALSE

Sheet Copy of (agoy fadli) Total Perm
A1: Permintaan | B1: Area | C1: DC ID | D1: Type | F1: ID Asal | G1: Nama Kota | H1: Id Tujuan | I1: Nama Kota Tujuan | J1: Jarak(KM) | L1: ID Asal | M1: Nama Kota | N1: Id Tujuan | O1: Nama Kota Tujuan | P1: Jarak(KM) | R1: ID Asal | S1: Lokasi Asal | T1: ID Tujuan | U1: Nama Kota | V1: Jarak (km)
A2: =ROUNDUP(4623,0) -> 4623 | B2: Ampah - Teweh | C2: DC001 | D2: Depo | F2: DC041 | G2: Palangkaraya | H2: DC001 | I2: Ampah | J2: 343.092 | L2: DC041 | M2: Palangkaraya | N2: DC001 | O2: Ampah | P2: 343.092 | R2: DC037 | S2: Balikpapan | T2: DC039 | U2: Penajam-Grogot | V2: 161958
A3: =ROUNDUP(1729,0) -> 1729 | B3: Amurang | C3: DC002 | D3: Depo | F3: DC033 | G3: Manado | H3: DC002 | I3: Amurang | J3: 55.4 | L3: DC033 | M3: Manado | N3: DC002 | O3: Amurang | P3: 55.4 | R3: DC038 | S3: Banjarmasin | T3: DC037 | U3: Barabai | V3: 144846
A4: 12496 | B4: Barabai | C4: DC003 | D4: Depo | F4: DC038 | G4: Banjarmasin | H4: DC003 | I4: Barabai | J4: 144.846 | L4: DC038 | M4: Banjarmasin | N4: DC003 | O4: Barabai | P4: 144.846 | R4: DC038 | S4: Banjarmasin | T4: DC037 | U4: Batulicin | V4: 203111
